# 异常关键字

## **throws关键字**

在方法声明上可以使用throws关键字来进行异常类型的标注。

**范例：**观察throws的使用

```java
class MyMath{
    public static int div(int x ,int y) throws Exception{
        return x / y;
    }
}
public class JavaDemo {
    public static void main(String args[]) {
        try {
            System.out.println(MyMath.div(10,2));
        }catch (Exception e){
            e.printStackTrace();
        }
    }
}
```

主方法也可以抛出异常

**范例：**在主方法上抛出异常

```java
class MyMath{
    public static int div(int x ,int y) throws Exception{
        return x / y;
    }
}
public class JavaDemo {
    public static void main(String args[]) throws Exception{
        System.out.println("-----");
        System.out.println(MyMath.div(10,0));
    }
}
```

## **throw关键字**

此关键字的主要作用为表示手工进行异常抛出，即：此时手工产生异常的实例化对象，并且进行异常的抛出处理

**范例：**观察throw的使用

```java
public class JavaDemo {
    public static void main(String args[]){
        try { // 异常对象是由手工定义的
            throw new Exception("自己抛着玩的对象");
        }catch (Exception e){
            e.printStackTrace();
        }
    }
}
```

**面试题：**请解释throw与throws的区别

- throw：是在代码块中使用的，主要是手工进行异常对象的抛出
- throws：是在方法定义上使用的，表示将此方法中可能产生的异常明确告诉调用处，由调用处进行处理

## **异常处理标准格式**

现在要求定义一个实现除法运算的方法，在这个方法中开发要求如下：

- 在进行数学计算开始与结束时进行信息提示；
- 如果进行计算过程中产生了异常，则交给调用处处理

```java
class MyMath{
    // 异常交给被调用处处理，则一定要在方法上使用throws
    public static int div(int x,int y) throws Exception{
        int temp = 0;
        System.out.println("【START】除法计算开始");
        try {
            temp = x / y;
        }catch (Exception e){
            throw e; // 向上抛异常对象
        } finally {
            System.out.println("【END】除法计算结束");
        }
        return temp;
    }
}
public class JavaDemo {
    public static void main(String args[]){
        try { // 异常对象是由手工定义的
            System.out.println(MyMath.div(10,0));
        }catch (Exception e){
            e.printStackTrace();
        }
    }
}
```

上述操作可以进行简化，省略掉catch与throw的操作

```java
class MyMath{
    // 异常交给被调用处处理，则一定要在方法上使用throws
    public static int div(int x,int y) throws Exception{
        int temp = 0;
        System.out.println("【START】除法计算开始");
        try {
            temp = x / y;
        }finally {
            System.out.println("【END】除法计算结束");
        }
        return temp;
    }
}
public class JavaDemo {
    public static void main(String args[]){
        try { // 异常对象是由手工定义的
            System.out.println(MyMath.div(10,0));
        }catch (Exception e){
            e.printStackTrace();
        }
    }
}
```

## **RuntimeException**

只要方法后面加上throws往往都是告诉用户本方法可能产生的异常是什么

**范例：**观察一个代码

```java
public class JavaDemo {
    public static void main(String args[]){
        int num = Integer.parseInt("123");
        System.out.println(num); // 123
    }
}
```

Interger中的parseInt()方法：public static int parseInt([String](https://docs.oracle.com/javase/8/docs/api/java/lang/String.html) s) throws [NumberFormatException](https://docs.oracle.com/javase/8/docs/api/java/lang/NumberFormatException.html)

这个方法上明确抛出了一个异常，但是在处理的时候没有强制性要求处理。

观察[NumberFormatException](https://docs.oracle.com/javase/8/docs/api/java/lang/NumberFormatException.html)继承结构

**Class NumberFormatException**

- [java.lang.Object](https://docs.oracle.com/javase/8/docs/api/java/lang/Object.html)

  - [java.lang.Throwable](https://docs.oracle.com/javase/8/docs/api/java/lang/Throwable.html)

    - [java.lang.Exception](https://docs.oracle.com/javase/8/docs/api/java/lang/Exception.html)
      - [java.lang.RuntimeException](https://docs.oracle.com/javase/8/docs/api/java/lang/RuntimeException.html)

        - [java.lang.IllegalArgumentException](https://docs.oracle.com/javase/8/docs/api/java/lang/IllegalArgumentException.html)

          - java.lang.NumberFormatException

如果现在所有的程序执行上只要使用了throws都要求开发者进行手工处理，那么代码的编写非常麻烦。为了考虑代码编写的方便，所以提供了一个可选的异常处理父类”RuntimeException“，这个类的异常的子类可以不需要强制性处理。

**面试题：**请解释RuntimeException与Exception的区别

- RuntimeException是Exception的子类，
- RuntimeException标注的异常可以不需要进行强制性处理，而Exception异常必须强制处理

常见的RuntimeException：

- NumberFormatException
- ClassCastException
- IndexOutOfBoundsException
- NullPointException

## **自定义异常类**

对自定义异常有两种实现方案：继承Exception或者继承RuntimeException。

**范例：**实现自定义异常

```java
class BombException extends Exception{
    public BombException(String msg){
        super(msg);
    }
}
class Food{
    public static void eat(int num) throws BombException{
        if (num > 10){
            throw new BombException("吃太多了，肚子爆了");
        }else {
            System.out.println("刚刚好");
        }
    }
}
public class JavaDemo {
    public static void main(String args[]) throws Exception{
        Food.eat(11);
    }
}
```

## **assert断言**

确定代码执行到某行时一定是所期待的结果。

**范例：**断言的使用

```java
public class JavaDemo {
    public static void main(String args[]) throws Exception{
        int x = 10;
        // 中间经过许多x变量的操作步骤
        assert x == 100:"x的内容不是100";
        System.out.println(x);

    }
}
```

如果想要执行断言，则必须在程序执行的时候加入参数：

**java -ea JavaDemo**

**在Java中并没有将断言设置为一个程序必须执行的步骤，而是需要特定环境下才可以开启**

